<?xml version="1.0" encoding="utf-8"?>
<!-- This URDF was automatically created by SolidWorks to URDF Exporter! Originally created by Stephen Brawner (brawner@gmail.com) 
     Commit Version: 1.6.0-4-g7f85cfe  Build Version: 1.6.7995.38578
     For more information, please see http://wiki.ros.org/sw_urdf_exporter -->
<robot name="M20_Piper">
  <mujoco>
    <compiler meshdir="../meshes/" balanceinertia="false" discardvisual="false" fusestatic="false"/>
  </mujoco>
  <link name="base_link">
    <inertial>
      <origin xyz="0.00355105878308153 0.0016507579200937 -0.00346462146571654" rpy="0 0 0"/>
      <mass value="15.882"/>
      <inertia ixx="0.0880787" ixy="0.001396" ixz="0.000111" iyy="0.533816" iyz="0.000519" izz="0.563915"/>
    </inertial>
    <visual>
      <origin xyz="0 0 0" rpy="0 0 0"/>
      <geometry>
        <mesh filename="../meshes/base_link.STL"/>
      </geometry>
      <material name="">
        <color rgba="0.752941176470588 0.752941176470588 0.752941176470588 1"/>
      </material>
    </visual>
    <collision>
      <origin xyz="0 0 0" rpy="0 0 0"/>
      <geometry>
        <box size="0.75 0.09 0.14"/>
      </geometry>
    </collision>
    <collision>
      <origin xyz="0 0.045 0" rpy="0 1.57079632 0"/>
      <geometry>
        <cylinder length="0.75" radius="0.07"/>
      </geometry>
    </collision>
    <collision>
      <origin xyz="0 -0.045 0" rpy="0 1.57079632 0"/>
      <geometry>
        <cylinder length="0.75" radius="0.07"/>
      </geometry>
    </collision>
  </link>
  <link name="fl_hipx">
    <inertial>
      <origin xyz="-0.0111893129496933 0.00891693461032669 0.000405665689861192" rpy="0 0 0"/>
      <mass value="0.261359958476582"/>
      <inertia ixx="0.000186" ixy="0.000025" ixz="-0.000012" iyy="0.000371" iyz="-0.000008" izz="0.000288"/>
    </inertial>
    <visual>
      <origin xyz="0 0 0" rpy="0 0 0"/>
      <geometry>
        <mesh filename="../meshes/fl_hipx.STL"/>
      </geometry>
      <material name="">
        <color rgba="0.752941176470588 0.752941176470588 0.752941176470588 1"/>
      </material>
    </visual>
    <collision>
      <origin xyz="0 0.055 0" rpy="1.57079632 0 0"/>
      <geometry>
        <cylinder length="0.14" radius="0.048"/>
      </geometry>
    </collision>
  </link>
  <joint name="fl_hipx_joint" type="revolute">
    <origin xyz="0.3141 0.0685 0" rpy="0 0 0"/>
    <parent link="base_link"/>
    <child link="fl_hipx"/>
    <axis xyz="-1 0 0"/>
    <limit lower="-0.611" upper="0.436" effort="76.4" velocity="22.4"/>
  </joint>
  <link name="fl_hipy">
    <inertial>
      <origin xyz="-0.00199374763010413 0.0984389609045802 -0.130663565833427" rpy="0 0 0"/>
      <mass value="2.493"/>
      <inertia ixx="0.038859" ixy="-0.000023" ixz="-0.000037" iyy="0.038040" iyz="-0.005985" izz="0.003848"/>
    </inertial>
    <visual>
      <origin xyz="0 0 0" rpy="0 0 0"/>
      <geometry>
        <mesh filename="../meshes/fl_hipy.STL"/>
      </geometry>
      <material name="">
        <color rgba="0.752941176470588 0.752941176470588 0.752941176470588 1"/>
      </material>
    </visual>
    <collision>
      <origin xyz="-0.01 0.11 -0.125" rpy="0 0 0"/>
      <geometry>
        <box size="0.07 0.02 0.25"/>
      </geometry>
    </collision>
    <collision>
      <origin xyz="0 0.11 -0.25" rpy="1.57079632 0 0"/>
      <geometry>
        <cylinder length="0.09" radius="0.05"/>
      </geometry>
    </collision>
  </link>
  <joint name="fl_hipy_joint" type="revolute">
    <origin xyz="0 0 0" rpy="0 0 0"/>
    <parent link="fl_hipx"/>
    <child link="fl_hipy"/>
    <axis xyz="0 -1 0"/>
    <limit lower="-2.583" upper="2.286" effort="76.4" velocity="22.4"/>
  </joint>
  <link name="fl_knee">
    <inertial>
      <origin xyz="0.00341916513259743 0.0026912421076368 -0.181265498605881" rpy="0 0 0"/>
      <mass value="1.26"/>
      <inertia ixx="0.012936" ixy="-0.000053" ixz="0.000226" iyy="0.013123" iyz="-0.001681" izz="0.001682"/>
    </inertial>
    <visual>
      <origin xyz="0 0 0" rpy="0 0 0"/>
      <geometry>
        <mesh filename="../meshes/fl_knee.STL"/>
      </geometry>
      <material name="">
        <color rgba="0.752941176470588 0.752941176470588 0.752941176470588 1"/>
      </material>
    </visual>
    <collision>
      <origin xyz="0.015 -0.015 -0.125" rpy="0 0 0"/>
      <geometry>
        <box size="0.06 0.025 0.25"/>
      </geometry>
    </collision>
    <collision>
      <origin xyz="0 0.02 -0.25" rpy="1.57079632 0 0"/>
      <geometry>
        <cylinder length="0.1" radius="0.04"/>
      </geometry>
    </collision>
  </link>
  <joint name="fl_knee_joint" type="revolute">
    <origin xyz="0 0.0984 -0.25" rpy="0 0 0"/>
    <parent link="fl_hipy"/>
    <child link="fl_knee"/>
    <axis xyz="0 -1 0"/>
    <limit lower="-2.792" upper="2.809" effort="76.4" velocity="22.4"/>
  </joint>
  <link name="fl_wheel">
    <inertial>
      <origin xyz="-3.11398454355682E-07 0.000279001520740008 5.70329233673394E-07" rpy="0 0 0"/>
      <mass value="0.638"/>
      <inertia ixx="0.001535" ixy="0.0" ixz="0.0" iyy="0.002853" iyz="0.0" izz="0.001535"/>
    </inertial>
    <visual>
      <origin xyz="0 0 0" rpy="0 0 0"/>
      <geometry>
        <mesh filename="../meshes/fl_wheel.STL"/>
      </geometry>
      <material name="">
        <color rgba="0.752941176470588 0.752941176470588 0.752941176470588 1"/>
      </material>
    </visual>
    <collision>
      <origin xyz="0 0 0" rpy="1.57079632 0 0"/>
      <geometry>
        <cylinder length="0.054" radius="0.09"/>
      </geometry>
    </collision>
  </link>
  <joint name="fl_wheel_joint" type="continuous">
    <origin xyz="0 0.059676 -0.25" rpy="0 0 0"/>
    <parent link="fl_knee"/>
    <child link="fl_wheel"/>
    <axis xyz="0 -1 0"/>
    <limit effort="21.6" velocity="79.3"/>
  </joint>
  <link name="fr_hipx">
    <inertial>
      <origin xyz="-0.0110900940309543 -0.0087503473771439 0.000521421017057358" rpy="0 0 0"/>
      <mass value="0.261359958476582"/>
      <inertia ixx="0.000186" ixy="-0.000026" ixz="-0.000012" iyy="0.000371" iyz="0.000008" izz="0.000288"/>
    </inertial>
    <visual>
      <origin xyz="0 0 0" rpy="0 0 0"/>
      <geometry>
        <mesh filename="../meshes/fr_hipx.STL"/>
      </geometry>
      <material name="">
        <color rgba="0.752941176470588 0.752941176470588 0.752941176470588 1"/>
      </material>
    </visual>
    <collision>
      <origin xyz="0 -0.055 0" rpy="1.57079632 0 0"/>
      <geometry>
        <cylinder length="0.14" radius="0.048"/>
      </geometry>
    </collision>
  </link>
  <joint name="fr_hipx_joint" type="revolute">
    <origin xyz="0.3141 -0.0685 0" rpy="0 0 0"/>
    <parent link="base_link"/>
    <child link="fr_hipx"/>
    <axis xyz="-1 0 0"/>
    <limit lower="-0.436" upper="0.611" effort="76.4" velocity="22.4"/>
  </joint>
  <link name="fr_hipy">
    <inertial>
      <origin xyz="-0.00229991904853988 -0.0989709441053532 -0.130925037640537" rpy="0 0 0"/>
      <mass value="2.493"/>
      <inertia ixx="0.039277" ixy="0.000005" ixz="-0.000063" iyy="0.038485" iyz="0.005970" izz="0.003921"/>
    </inertial>
    <visual>
      <origin xyz="0 0 0" rpy="0 0 0"/>
      <geometry>
        <mesh filename="../meshes/fr_hipy.STL"/>
      </geometry>
      <material name="">
        <color rgba="0.752941176470588 0.752941176470588 0.752941176470588 1"/>
      </material>
    </visual>
    <collision>
      <origin xyz="-0.01 -0.11 -0.125" rpy="0 0 0"/>
      <geometry>
        <box size="0.07 0.02 0.25"/>
      </geometry>
    </collision>
    <collision>
      <origin xyz="0 -0.11 -0.25" rpy="1.57079632 0 0"/>
      <geometry>
        <cylinder length="0.09" radius="0.05"/>
      </geometry>
    </collision>
  </link>
  <joint name="fr_hipy_joint" type="revolute">
    <origin xyz="0 0 0" rpy="0 0 0"/>
    <parent link="fr_hipx"/>
    <child link="fr_hipy"/>
    <axis xyz="0 -1 0"/>
    <limit lower="-2.583" upper="2.286" effort="76.4" velocity="22.4"/>
  </joint>
  <link name="fr_knee">
    <inertial>
      <origin xyz="0.0035494546955584 -0.002478843181213 -0.180089236444296" rpy="0 0 0"/>
      <mass value="1.26"/>
      <inertia ixx="0.012936" ixy="0.000053" ixz="0.000226" iyy="0.013123" iyz="0.001681" izz="0.001283"/>
    </inertial>
    <visual>
      <origin xyz="0 0 0" rpy="0 0 0"/>
      <geometry>
        <mesh filename="../meshes/fr_knee.STL"/>
      </geometry>
      <material name="">
        <color rgba="0.752941176470588 0.752941176470588 0.752941176470588 1"/>
      </material>
    </visual>
    <collision>
      <origin xyz="0.015 0.015 -0.125" rpy="0 0 0"/>
      <geometry>
        <box size="0.06 0.025 0.25"/>
      </geometry>
    </collision>
    <collision>
      <origin xyz="0 -0.02 -0.25" rpy="1.57079632 0 0"/>
      <geometry>
        <cylinder length="0.1" radius="0.04"/>
      </geometry>
    </collision>
  </link>
  <joint name="fr_knee_joint" type="revolute">
    <origin xyz="0 -0.0984 -0.25" rpy="0 0 0"/>
    <parent link="fr_hipy"/>
    <child link="fr_knee"/>
    <axis xyz="0 -1 0"/>
    <limit lower="-2.792" upper="2.809" effort="76.4" velocity="22.4"/>
  </joint>
  <link name="fr_wheel">
    <inertial>
      <origin xyz="-6.4732687427016E-07 -0.000279012463466427 -4.62420470803693E-08" rpy="0 0 0"/>
      <mass value="0.638"/>
      <inertia ixx="0.001535" ixy="0.0" ixz="0.0" iyy="0.002853" iyz="0.0" izz="0.001535"/>
    </inertial>
    <visual>
      <origin xyz="0 0 0" rpy="0 0 0"/>
      <geometry>
        <mesh filename="../meshes/fr_wheel.STL"/>
      </geometry>
      <material name="">
        <color rgba="0.752941176470588 0.752941176470588 0.752941176470588 1"/>
      </material>
    </visual>
    <collision>
      <origin xyz="0 0 0" rpy="1.57079632 0 0"/>
      <geometry>
        <cylinder length="0.054" radius="0.09"/>
      </geometry>
    </collision>
  </link>
  <joint name="fr_wheel_joint" type="continuous">
    <origin xyz="0 -0.059676 -0.25" rpy="0 0 0"/>
    <parent link="fr_knee"/>
    <child link="fr_wheel"/>
    <axis xyz="0 -1 0"/>
    <limit effort="21.6" velocity="79.3"/>
  </joint>
  <link name="hl_hipx">
    <inertial>
      <origin xyz="0.0110900940233134 0.00875014035040743 0.000524883746291591" rpy="0 0 0"/>
      <mass value="0.261359958476582"/>
      <inertia ixx="0.000186" ixy="-0.000025" ixz="0.000012" iyy="0.000371" iyz="-0.000008" izz="0.000288"/>
    </inertial>
    <visual>
      <origin xyz="0 0 0" rpy="0 0 0"/>
      <geometry>
        <mesh filename="../meshes/hl_hipx.STL"/>
      </geometry>
      <material name="">
        <color rgba="0.752941176470588 0.752941176470588 0.752941176470588 1"/>
      </material>
    </visual>
    <collision>
      <origin xyz="0 0.055 0" rpy="1.57079632 0 0"/>
      <geometry>
        <cylinder length="0.14" radius="0.048"/>
      </geometry>
    </collision>
  </link>
  <joint name="hl_hipx_joint" type="revolute">
    <origin xyz="-0.3141 0.0685 0" rpy="0 0 0"/>
    <parent link="base_link"/>
    <child link="hl_hipx"/>
    <axis xyz="-1 0 0"/>
    <limit lower="-0.611" upper="0.436" effort="76.4" velocity="22.4"/>
  </joint>
  <link name="hl_hipy">
    <inertial>
      <origin xyz="0.00204343366218146 0.0990227473833045 -0.13069726691312" rpy="0 0 0"/>
      <mass value="2.493"/>
      <inertia ixx="0.039361" ixy="0.000029" ixz="0.000009" iyy="0.038554" iyz="-0.006001" izz="0.003914"/>
    </inertial>
    <visual>
      <origin xyz="0 0 0" rpy="0 0 0"/>
      <geometry>
        <mesh filename="../meshes/hl_hipy.STL"/>
      </geometry>
      <material name="">
        <color rgba="0.752941176470588 0.752941176470588 0.752941176470588 1"/>
      </material>
    </visual>
    <collision>
      <origin xyz="0.01 0.11 -0.125" rpy="0 0 0"/>
      <geometry>
        <box size="0.07 0.02 0.25"/>
      </geometry>
    </collision>
    <collision>
      <origin xyz="0 0.11 -0.25" rpy="1.57079632 0 0"/>
      <geometry>
        <cylinder length="0.09" radius="0.05"/>
      </geometry>
    </collision>
  </link>
  <joint name="hl_hipy_joint" type="revolute">
    <origin xyz="0 0 0" rpy="0 0 0"/>
    <parent link="hl_hipx"/>
    <child link="hl_hipy"/>
    <axis xyz="0 -1 0"/>
    <limit lower="-2.286" upper="2.583" effort="76.4" velocity="22.4"/>
  </joint>
  <link name="hl_knee">
    <inertial>
      <origin xyz="-0.00354945209738589 0.00247884637205834 -0.180089257150601" rpy="0 0 0"/>
      <mass value="1.26"/>
      <inertia ixx="0.012936" ixy="0.000053" ixz="-0.000226" iyy="0.013123" iyz="-0.001681" izz="0.001283"/>
    </inertial>
    <visual>
      <origin xyz="0 0 0" rpy="0 0 0"/>
      <geometry>
        <mesh filename="../meshes/hl_knee.STL"/>
      </geometry>
      <material name="">
        <color rgba="0.752941176470588 0.752941176470588 0.752941176470588 1"/>
      </material>
    </visual>
    <collision>
      <origin xyz="-0.015 0.015 -0.125" rpy="0 0 0"/>
      <geometry>
        <box size="0.06 0.025 0.25"/>
      </geometry>
    </collision>
    <collision>
      <origin xyz="0 0.02 -0.25" rpy="1.57079632 0 0"/>
      <geometry>
        <cylinder length="0.1" radius="0.04"/>
      </geometry>
    </collision>
  </link>
  <joint name="hl_knee_joint" type="revolute">
    <origin xyz="0 0.0984 -0.25" rpy="0 0 0"/>
    <parent link="hl_hipy"/>
    <child link="hl_knee"/>
    <axis xyz="0 -1 0"/>
    <limit lower="-2.809" upper="2.792" effort="76.4" velocity="22.4"/>
  </joint>
  <link name="hl_wheel">
    <inertial>
      <origin xyz="-6.07889369508285E-07 0.000279009097070765 2.10489879304276E-07" rpy="0 0 0"/>
      <mass value="0.638"/>
      <inertia ixx="0.001535" ixy="0.0" ixz="0.0" iyy="0.002853" iyz="0.0" izz="0.001535"/>
    </inertial>
    <visual>
      <origin xyz="0 0 0" rpy="0 0 0"/>
      <geometry>
        <mesh filename="../meshes/hl_wheel.STL"/>
      </geometry>
      <material name="">
        <color rgba="0.752941176470588 0.752941176470588 0.752941176470588 1"/>
      </material>
    </visual>
    <collision>
      <origin xyz="0 0 0" rpy="1.57079632 0 0"/>
      <geometry>
        <cylinder length="0.054" radius="0.09"/>
      </geometry>
    </collision>
  </link>
  <joint name="hl_wheel_joint" type="continuous">
    <origin xyz="0 0.059676 -0.25" rpy="0 0 0"/>
    <parent link="hl_knee"/>
    <child link="hl_wheel"/>
    <axis xyz="0 -1 0"/>
    <limit effort="21.6" velocity="79.3"/>
  </joint>
  <link name="hr_hipx">
    <inertial>
      <origin xyz="0.0110901558226165 -0.00875011717083631 0.000524936954718227" rpy="0 0 0"/>
      <mass value="0.261359958476582"/>
      <inertia ixx="0.000186" ixy="0.000025" ixz="0.000012" iyy="0.000371" iyz="0.000008" izz="0.000288"/>
    </inertial>
    <visual>
      <origin xyz="0 0 0" rpy="0 0 0"/>
      <geometry>
        <mesh filename="../meshes/hr_hipx.STL"/>
      </geometry>
      <material name="">
        <color rgba="0.752941176470588 0.752941176470588 0.752941176470588 1"/>
      </material>
    </visual>
    <collision>
      <origin xyz="0 -0.055 0" rpy="1.57079632 0 0"/>
      <geometry>
        <cylinder length="0.14" radius="0.048"/>
      </geometry>
    </collision>
  </link>
  <joint name="hr_hipx_joint" type="revolute">
    <origin xyz="-0.3141 -0.0685 0" rpy="0 0 0"/>
    <parent link="base_link"/>
    <child link="hr_hipx"/>
    <axis xyz="-1 0 0"/>
    <limit lower="-0.436" upper="0.611" effort="76.4" velocity="22.4"/>
  </joint>
  <link name="hr_hipy">
    <inertial>
      <origin xyz="0.00199199678434109 -0.0983704174694303 -0.13056065751366" rpy="0 0 0"/>
      <mass value="2.493"/>
      <inertia ixx="0.038878" ixy="-0.000022" ixz="0.000034" iyy="0.038053" iyz="0.005995" izz="0.003854"/>
    </inertial>
    <visual>
      <origin xyz="0 0 0" rpy="0 0 0"/>
      <geometry>
        <mesh filename="../meshes/hr_hipy.STL"/>
      </geometry>
      <material name="">
        <color rgba="0.752941176470588 0.752941176470588 0.752941176470588 1"/>
      </material>
    </visual>
    <collision>
      <origin xyz="0.01 -0.11 -0.125" rpy="0 0 0"/>
      <geometry>
        <box size="0.07 0.02 0.25"/>
      </geometry>
    </collision>
    <collision>
      <origin xyz="0 -0.11 -0.25" rpy="1.57079632 0 0"/>
      <geometry>
        <cylinder length="0.09" radius="0.05"/>
      </geometry>
    </collision>
  </link>
  <joint name="hr_hipy_joint" type="revolute">
    <origin xyz="0 0 0" rpy="0 0 0"/>
    <parent link="hr_hipx"/>
    <child link="hr_hipy"/>
    <axis xyz="0 -1 0"/>
    <limit lower="-2.286" upper="2.583" effort="76.4" velocity="22.4"/>
  </joint>
  <link name="hr_knee">
    <inertial>
      <origin xyz="-0.00341053036115846 -0.0027020185369851 -0.181287492263963" rpy="0 0 0"/>
      <mass value="1.26"/>
      <inertia ixx="0.012936" ixy="-0.000053" ixz="-0.000226" iyy="0.013123" iyz="0.001681" izz="0.001283"/>
    </inertial>
    <visual>
      <origin xyz="0 0 0" rpy="0 0 0"/>
      <geometry>
        <mesh filename="../meshes/hr_knee.STL"/>
      </geometry>
      <material name="">
        <color rgba="0.752941176470588 0.752941176470588 0.752941176470588 1"/>
      </material>
    </visual>
    <collision>
      <origin xyz="-0.015 0.015 -0.125" rpy="0 0 0"/>
      <geometry>
        <box size="0.06 0.025 0.25"/>
      </geometry>
    </collision>
    <collision>
      <origin xyz="0 -0.02 -0.25" rpy="1.57079632 0 0"/>
      <geometry>
        <cylinder length="0.1" radius="0.04"/>
      </geometry>
    </collision>
  </link>
  <joint name="hr_knee_joint" type="revolute">
    <origin xyz="0 -0.0984 -0.25" rpy="0 0 0"/>
    <parent link="hr_hipy"/>
    <child link="hr_knee"/>
    <axis xyz="0 -1 0"/>
    <limit lower="-2.809" upper="2.792" effort="76.4" velocity="22.4"/>
  </joint>
  <link name="hr_wheel">
    <inertial>
      <origin xyz="6.09746291457824E-07 -0.00027900886004309 2.0131377032051E-07" rpy="0 0 0"/>
      <mass value="0.638"/>
      <inertia ixx="0.001535" ixy="0.0" ixz="0.0" iyy="0.002853" iyz="0.0" izz="0.001535"/>
    </inertial>
    <visual>
      <origin xyz="0 0 0" rpy="0 0 0"/>
      <geometry>
        <mesh filename="../meshes/hr_wheel.STL"/>
      </geometry>
      <material name="">
        <color rgba="0.752941176470588 0.752941176470588 0.752941176470588 1"/>
      </material>
    </visual>
    <collision>
      <origin xyz="0 0 0" rpy="1.57079632 0 0"/>
      <geometry>
        <cylinder length="0.054" radius="0.09"/>
      </geometry>
    </collision>
  </link>
  <joint name="hr_wheel_joint" type="continuous">
    <origin xyz="0 -0.059676 -0.25" rpy="0 0 0"/>
    <parent link="hr_knee"/>
    <child link="hr_wheel"/>
    <axis xyz="0 -1 0"/>
    <limit effort="21.6" velocity="79.3"/>
  </joint>

  <joint name="base_to_arm" type="fixed">
    <parent link="base_link"/>
    <child link="arm_base_link"/>
    <origin xyz="0.0 0.0 0.0888" rpy="0 0 0"/>
  </joint>
  <link name="arm_base_link">
    <inertial>
      <origin xyz="-0.00473641164191482 2.56829134630247E-05 0.041451518036016" rpy="0 0 0" />
      <mass value="1.02" />
      <inertia ixx="0.00267433" ixy="-0.00000073" ixz="-0.00017389" iyy="0.00282612" iyz="0.0000004" izz="0.00089624" />
    </inertial>
    <visual>
      <origin xyz="0 0 0" rpy="0 0 0" />
      <geometry>
        <mesh filename="../meshes/arm_base_link.STL" />
      </geometry>
      <material name="">
        <color rgba="0.792156862745098 0.819607843137255 0.933333333333333 1" />
      </material>
    </visual>
    <collision>
      <origin xyz="0 0 0" rpy="0 0 0" />
      <geometry>
        <mesh filename="../meshes/arm_base_link.STL" />
      </geometry>
    </collision>
  </link>

  <link name="link1">
    <inertial>
      <origin xyz="0.000121504734057468 0.000104632162460536 -0.00438597309559853" rpy="0 0 0" />
      <mass value="0.71" />
      <inertia ixx="0.00048916" ixy="-0.00000036" ixz="-0.00000224" iyy="0.00040472" iyz="-0.00000242" izz="0.00043982" />
    </inertial>
    <visual>
      <origin xyz="0 0 0" rpy="0 0 0" />
      <geometry>
        <mesh filename="../meshes/link1.STL" />
      </geometry>
      <material name="">
        <color rgba="0.792156862745098 0.819607843137255 0.933333333333333 1" />
      </material>
    </visual>
    <collision>
      <origin xyz="0 0 0" rpy="0 0 0" />
      <geometry>
        <mesh filename="../meshes/link1.STL" />
      </geometry>
    </collision>
  </link>
  <joint name="joint1" type="revolute">
    <origin xyz="0 0 0.123" rpy="0 0 0" />
    <parent link="arm_base_link" />
    <child link="link1" />
    <axis xyz="0 0 1" />
    <limit lower="-2.618" upper="2.618" effort="100" velocity="5" />
  </joint>
  <link name="link2">
    <inertial>
      <origin xyz="0.198666145229743 -0.010926924140076 0.00142121714502687" rpy="0 0 0" />
      <mass value="1.17" />
      <inertia ixx="0.00116918" ixy="-0.00180037" ixz="0.00025146" iyy="0.06785384" iyz="-0.00000455" izz="0.06774489" />
    </inertial>
    <visual>
      <origin xyz="0 0 0" rpy="0 0 0" />
      <geometry>
        <mesh filename="../meshes/link2.STL" />
      </geometry>
      <material name="">
        <color rgba="0.792156862745098 0.819607843137255 0.933333333333333 1" />
      </material>
    </visual>
    <collision>
      <origin xyz="0 0 0" rpy="0 0 0" />
      <geometry>
        <mesh filename="../meshes/link2.STL" />
      </geometry>
    </collision>
  </link>
  <joint name="joint2" type="revolute">
    <origin xyz="0 0 0" rpy="1.5708 -0.1359 -3.1416" />
    <parent link="link1" />
    <child link="link2" />
    <axis xyz="0 0 1" />
    <limit lower="0" upper="3.14" effort="100" velocity="5" />
  </joint>
  <link name="link3">
    <inertial>
      <origin xyz="-0.0202737662122021 -0.133914995944595 -0.000458682652737356" rpy="0 0 0" />
      <mass value="0.5" />
      <inertia ixx="0.01361711" ixy="0.00165794" ixz="-0.00000048" iyy="0.00045024" iyz="-0.00000045" izz="0.01380322" />
    </inertial>
    <visual>
      <origin xyz="0 0 0" rpy="0 0 0" />
      <geometry>
        <mesh filename="../meshes/link3.STL" />
      </geometry>
      <material name="">
        <color rgba="0.792156862745098 0.819607843137255 0.933333333333333 1" />
      </material>
    </visual>
    <collision>
      <origin xyz="0 0 0" rpy="0 0 0" />
      <geometry>
        <mesh filename="../meshes/link3.STL" />
      </geometry>
    </collision>
  </link>
  <joint name="joint3" type="revolute">
    <origin xyz="0.28503 0 0" rpy="0 0 -1.7939" />
    <parent link="link2" />
    <child link="link3" />
    <axis xyz="0 0 1" />
    <limit lower="-2.967" upper="0" effort="100" velocity="5" />
  </joint>
  <link name="link4">
    <inertial>
      <origin xyz="-9.66635791618542E-05 0.000876064475651083 -0.00496880904640868" rpy="0 0 0" />
      <mass value="0.38" />
      <inertia ixx="0.00018501" ixy="0.00000054" ixz="0.00000120" iyy="0.00018965" iyz="-0.00000841" izz="0.00015484" />
    </inertial>
    <visual>
      <origin xyz="0 0 0" rpy="0 0 0" />
      <geometry>
        <mesh filename="../meshes/link4.STL" />
      </geometry>
      <material name="">
        <color rgba="0.792156862745098 0.819607843137255 0.933333333333333 1" />
      </material>
    </visual>
    <collision>
      <origin xyz="0 0 0" rpy="0 0 0" />
      <geometry>
        <mesh filename="../meshes/link4.STL" />
      </geometry>
    </collision>
  </link>
  <joint name="joint4" type="revolute">
    <origin xyz="-0.021984 -0.25075 0" rpy="1.5708 0 0" />
    <parent link="link3" />
    <child link="link4" />
    <axis xyz="0 0 1" />
    <limit lower="-1.745" upper="1.745" effort="100" velocity="5" />
  </joint>
  <link name="link5">
    <inertial>
      <origin xyz="-4.10554118924211E-05 -0.0566486692356075 -0.0037205791677906" rpy="0 0 0" />
      <mass value="0.383" />
      <inertia ixx="0.00166169" ixy="0.00000006" ixz="-0.00000007" iyy="0.00018510" iyz="0.00001026" izz="0.00164321" />
    </inertial>
    <visual>
      <origin xyz="0 0 0" rpy="0 0 0" />
      <geometry>
        <mesh filename="../meshes/link5.STL" />
      </geometry>
      <material name="">
        <color rgba="0.792156862745098 0.819607843137255 0.933333333333333 1" />
      </material>
    </visual>
    <collision>
      <origin xyz="0 0 0" rpy="0 0 0" />
      <geometry>
        <mesh filename="../meshes/link5.STL" />
      </geometry>
    </collision>
  </link>
  <joint name="joint5" type="revolute">
    <origin xyz="0 0 0" rpy="-1.5708 0 0" />
    <parent link="link4" />
    <child link="link5" />
    <axis xyz="0 0 1" />
    <limit lower="-1.22" upper="1.22" effort="100" velocity="5" />
  </joint>
  <link name="link6">
    <inertial>
      <origin xyz="-8.82590762930069E-05 9.0598378529832E-06 -0.002" rpy="0 0 0" />
      <mass value="0.007" />
      <inertia ixx="5.73015540542155E-07" ixy="-1.98305403089247E-22" ixz="-7.2791893904596E-23" iyy="5.73015540542155E-07" iyz="-3.4146026640245E-24" izz="1.06738869138926E-06" />
    </inertial>
    <visual>
      <origin xyz="0 0 0" rpy="0 0 0" />
      <geometry>
        <mesh filename="../meshes/link6.STL" />
      </geometry>
      <material name="">
        <color rgba="0.898039215686275 0.917647058823529 0.929411764705882 1" />
      </material>
    </visual>
    <collision>
      <origin xyz="0 0 0" rpy="0 0 0" />
      <geometry>
        <mesh filename="../meshes/link6.STL" />
      </geometry>
    </collision>
  </link>
  <joint name="joint6" type="revolute">
    <origin xyz="8.8259E-05 -0.091 0" rpy="1.5708 0 0" />
    <parent link="link5" />
    <child link="link6" />
    <axis xyz="0 0 1" />
    <limit lower="-2.0944" upper="2.0944" effort="100" velocity="3" />
  </joint>
  <link name="gripper_base">
    <inertial>
      <origin xyz="-0.000183807162235591 8.05033155577911E-05 0.0321436689908876" rpy="0 0 0" />
      <mass value="0.45" />
      <inertia ixx="0.00092934" ixy="0.00000034" ixz="-0.00000738" iyy="0.00071447" iyz="0.00000005" izz="0.00039442" />
    </inertial>
    <visual>
      <origin xyz="0 0 0" rpy="0 0 0" />
      <geometry>
        <mesh filename="../meshes/gripper_base.STL" />
      </geometry>
      <material name="">
        <color rgba="0.792156862745098 0.819607843137255 0.933333333333333 1" />
      </material>
    </visual>
    <collision>
      <origin xyz="0 0 0" rpy="0 0 0" />
      <geometry>
        <mesh filename="../meshes/gripper_base.STL" />
      </geometry>
    </collision>
  </link>
  <joint name="joint6_to_gripper_base" type="fixed">
    <origin xyz="0 0 0" rpy="0 0 0" />
    <parent link="link6" />
    <child link="gripper_base" />
  </joint>
  <link name="link7">
    <inertial>
      <origin xyz="0.00065123185041968 -0.0491929869131989 0.00972258769184025" rpy="0 0 0" />
      <mass value="0.025" />
      <inertia ixx="0.00007371" ixy="-0.00000113" ixz="0.00000021" iyy="0.00000781" iyz="-0.00001372" izz="0.0000747" />
    </inertial>
    <visual>
      <origin xyz="0 0 0" rpy="0 0 0" />
      <geometry>
        <mesh filename="../meshes/link7.STL" />
      </geometry>
      <material name="">
        <color rgba="0.792156862745098 0.819607843137255 0.933333333333333 1" />
      </material>
    </visual>
    <collision>
      <origin xyz="0 0 0" rpy="0 0 0" />
      <geometry>
        <mesh filename="../meshes/link7.STL" />
      </geometry>
    </collision>
  </link>
  <joint name="joint7" type="prismatic">
    <origin xyz="0 0 0.1358" rpy="1.5708 0 0" />
    <parent link="gripper_base" />
    <child link="link7" />
    <axis xyz="0 0 1" />
    <limit lower="0" upper="0.035" effort="10" velocity="1" />
  </joint>
  <link name="link8">
    <inertial>
      <origin xyz="0.000651231850419722 -0.0491929869131991 0.00972258769184024" rpy="0 0 0" />
      <mass value="0.025" />
      <inertia ixx="0.00007371" ixy="-0.00000113" ixz="0.00000021" iyy="0.00000781" iyz="-0.00001372" izz="0.0000747" />
    </inertial>
    <visual>
      <origin xyz="0 0 0" rpy="0 0 0" />
      <geometry>
        <mesh filename="../meshes/link8.STL" />
      </geometry>
      <material name="">
        <color rgba="0.792156862745098 0.819607843137255 0.933333333333333 1" />
      </material>
    </visual>
    <collision>
      <origin xyz="0 0 0" rpy="0 0 0" />
      <geometry>
        <mesh filename="../meshes/link8.STL" />
      </geometry>
    </collision>
  </link>
  <joint name="joint8" type="prismatic">
    <origin xyz="0 0 0.1358" rpy="1.5708 0 -3.1416" />
    <parent link="gripper_base" />
    <child link="link8" />
    <axis xyz="0 0 -1" />
    <limit lower="-0.035" upper="0" effort="10" velocity="1" />
  </joint>
</robot>
